Workbook

Sheet All float token
A1: Token | B1: TokenName | C1: Type
B2: ADA | C2: origin
A3: 25c5de5f5b286073c593edfd77b48abc7a48e5a4f3d4cd9d428ff935.425443 | B3: BTC | C3: origin
A4: 8db269c3ec630e06ae29f74bc39edd1f87c819f1056206e879a1cd61.446a65644d6963726f555344 | B4: DJED | C4: origin
A5: fe7c786ab321f41c654ef6c1af7b3250a613c24e4213e0425a7ae456.55534441 | B5: USDA | C5: origin
A6: 25c5de5f5b286073c593edfd77b48abc7a48e5a4f3d4cd9d428ff935.55534443 | B6: USDC | C6: origin
A7: c48cbb3d5e57ed56e276bc45f99ab39abe94e6cd7ac39fb402da47ad.0014df105553444d | B7: USDM | C7: origin
A8: 25c5de5f5b286073c593edfd77b48abc7a48e5a4f3d4cd9d428ff935.55534454 | B8: USDT | C8: origin
A9: f5808c2c990d86da54bfc97d89cee6efa20cd8461616359478d96b4c.a939812d08cfb6066e17d2914a7272c6b8c0197acdf68157d02c73649cc3efc0 | B9: [minLP]ADA.DJED | C9: collateral only
A10: f5808c2c990d86da54bfc97d89cee6efa20cd8461616359478d96b4c.ee5cfbc5b0dc10c873a0bcc69e49b9af21b899f59337a894874c6b596c2da136 | B10: [minLP]ADA.USDA | C10: collateral only
A11: f5808c2c990d86da54bfc97d89cee6efa20cd8461616359478d96b4c.478773ab4e6f800e72e4210a80adc5b086eb6f42bf493591dbdcec4ae9a692f7 | B11: [minLP]ADA.USDC | C11: collateral only
A12: f5808c2c990d86da54bfc97d89cee6efa20cd8461616359478d96b4c.7dd6988c5a86693c76aeec1ea94afa41770be0de21a775ca7a2a1eabdb6a0171 | B12: [minLP]ADA.USDM | C12: collateral only
A13: f5808c2c990d86da54bfc97d89cee6efa20cd8461616359478d96b4c.3cb4b74763277162c3d4548c2af1829b79c41e2dd1ac7560504cbd5e82b1e971 | B13: [minLP]ADA.USDT | C13: collateral only
A14: f5808c2c990d86da54bfc97d89cee6efa20cd8461616359478d96b4c.55058d3f832e6bb577ca8bb354c0c736dc4ca4e80798a82c17a956ee278872d3 | B14: [minLP]BTC.ADA | C14: collateral only
... A36: 94dca24a1f1fcc2ff51cd90f32f4fe9e786d861a2dbf7d27598d26e8.134ab43b73bd6f5ae70534fe51194ad62618d39a539830ecef4f8e19 | B36: dBTC | C36: dToken
A37: 94dca24a1f1fcc2ff51cd90f32f4fe9e786d861a2dbf7d27598d26e8.2d94b144d91520d0de771f6c3449d5cff8f0373c472dae2b9851a8c2 | B37: dUSDT | C37: dToken | E37: borrow
A38: 279c909f348e533da5808898f87f9a14bb2c3dfbbacccd631d927a3f.534e454b | B38: Snek | C38: origin | E38: tới bước ký
A39: f13ac4d66b3ee19a6aa0f2a22298737bd907cc95121662fc971b5275.535452494b45 | B39: STRIKE | C39: origin | E39: tới bước ký
A40: 5d16cc1a177b5d9ba9cfa9793b07e60f1fb70fea1f8aef064415d114.494147 | B40: IAGON | C40: origin | E40: load đc màn hình
A41: 2d9db8a89f074aa045eab177f23a3395f62ced8b53499a9e4ad46c80.464c4f57 | B41: FLOW | C41: origin | E41: load đc màn hình
A42: 5deab590a137066fef0e56f06ef1b830f21bc5d544661ba570bdd2ae.424f44454741 | B42: BODEGA | C42: origin | E42: load đc màn hình
A43: 29d222ce763455e3d7a09a665ce554f00ac89d2e99a1a83d267170c6.4d494e | B43: Minswap | C43: origin | E43: tới bước ký
A44: da8c30857834c6ae7203935b89278c532b3995245295456f993e1d24.4c51 | B44: Liqwid DAO Token | C44: origin | D44: tới bước ký
A45: 533bb94a8850ee3ccbe483106489399112b74c905342cb1792a797a0.494e4459 | B45: Indigo DAO Token | C45: origin | E45: load đc màn hình
A46: 577f0b1342f8f8f4aed3388b80a8535812950c7a892495c0ecdf0f1e.0014df10464c4454 | B46: FLDT | C46: origin | E46: tới bước ký
A47: 95a427e384527065f2f8946f5e86320d0117839a5e98ea2c0b55fb00.48554e54 | B47: HUNT | C47: origin | E47: tới bước ký
A48: 2852268cf6e2db42e20f2fd3125f541e5d6c5a3d70b4dda17c2daa82 | B48: The O Token | C48: origin | E48: chưa có giá
A49: ececc92aeaaac1f5b665f567b01baec8bc2771804b4c21716a87a4e3.53504c415348 | B49: SPLASH | C49: origin | E49: tới bước ký
A50: f6099832f9563e4cf59602b3351c3c5a8a7dda2d44575ef69b82cf8d | B50: OADA | C50: origin | E50: tới bước ký
A51: 94dca24a1f1fcc2ff51cd90f32f4fe9e786d861a2dbf7d27598d26e8.2e614ed06d9ab2b693f108251c6df8d5e37cae81ffce99a4cf0a781f | B51: dSNEK | C51: dToken
A52: 94dca24a1f1fcc2ff51cd90f32f4fe9e786d861a2dbf7d27598d26e8.83b8a0a2074061394fddfe9aebee6fab4924dd73ec1326162f453dc9 | B52: dSTRIKE | C52: dToken
A53: 94dca24a1f1fcc2ff51cd90f32f4fe9e786d861a2dbf7d27598d26e8.4c56da0af61dfca72b32de9fc0c44ecdd248932e69ce267d62b7ddc1 | B53: dIAG | C53: dToken
A54: 94dca24a1f1fcc2ff51cd90f32f4fe9e786d861a2dbf7d27598d26e8.18e8d03ef4d8ab3c408551378040ae6a8dd1bb437023858bf4994df7 | B54: dFLOW | C54: dToken
A55: 94dca24a1f1fcc2ff51cd90f32f4fe9e786d861a2dbf7d27598d26e8.34d8725885174384ff7cd92e8b0b7a1d71a12550c9d61360ad4cf43c | B55: dBODEGA | C55: dToken
A56: 94dca24a1f1fcc2ff51cd90f32f4fe9e786d861a2dbf7d27598d26e8.251d5ccb51543f3647b344d4a4c8f2df5bff9d164854e3e7fe4b1711 | B56: dMIN | C56: dToken
A57: 94dca24a1f1fcc2ff51cd90f32f4fe9e786d861a2dbf7d27598d26e8.6487e97f20fba709c9edf5da2b72ad2a120ab4c5c38fe381fb76b25d | B57: dLQ | C57: dToken
A58: 94dca24a1f1fcc2ff51cd90f32f4fe9e786d861a2dbf7d27598d26e8.a1bc0130b1eb217e58c2b40f4e6ed7647af5c71157466bd6a0dbb85c | B58: dINDY | C58: dToken
A59: 94dca24a1f1fcc2ff51cd90f32f4fe9e786d861a2dbf7d27598d26e8.45af09272aeaf60d2215ce33daa6d2bc3ced61e5b59be434d21cd2e8 | B59: dFLDT | C59: dToken
A60: 94dca24a1f1fcc2ff51cd90f32f4fe9e786d861a2dbf7d27598d26e8.9c00007e09c95cc0c282fad790760cfbf33495c3161a77b4c87cfaed | B60: dHUNT | C60: dToken
A61: 94dca24a1f1fcc2ff51cd90f32f4fe9e786d861a2dbf7d27598d26e8.3cfdbb46c8359e7f5e56d48a330cf85fc38eef19c83730198bc0dcbb | B61: dO | C61: dToken
...

Sheet ListTokenPairs
A1: baseToken | B1: quoteToken | C1: threshold | D1: isActive | E1: base token name | F1: quote token name
A2: 09f4212b4f1c4a2d1300866e8decec795abb8eb8bbdc34d2d66384fd.555344545f4144415f4c51 | C2: 8000 | D2: TRUE | E2: =IF(A2="","ADA",VLOOKUP(A2,'All float token'!A$2:B$64,2,FALSE)) -> [splLP]ADA.USDT | F2: =IF(B2="","ADA",VLOOKUP(B2,'All float token'!A$2:B$64,2,FALSE)) -> ADA
A3: 0a0a692605bed9e698a172a35adbdb70a04b40273c9043e1c4e4570a.0014efbfbd105553444d5f4144415f4c51 | C3: 8000 | D3: TRUE | E3: =IF(A3="","ADA",VLOOKUP(A3,'All float token'!A$2:B$64,2,FALSE)) -> [splLP]ADA.USDM.500 | F3: =IF(B3="","ADA",VLOOKUP(B3,'All float token'!A$2:B$64,2,FALSE)) -> ADA
A4: 0d91892d31eef2398d66e771a03feea04ca17cd26655c2cc1550514a.555344415f4144415f4c51 | C4: 8000 | D4: TRUE | E4: =IF(A4="","ADA",VLOOKUP(A4,'All float token'!A$2:B$64,2,FALSE)) -> [splLP]ADA.USDA | F4: =IF(B4="","ADA",VLOOKUP(B4,'All float token'!A$2:B$64,2,FALSE)) -> ADA
A5: 25c5de5f5b286073c593edfd77b48abc7a48e5a4f3d4cd9d428ff935.425443 | C5: 8000 | D5: TRUE | E5: =IF(A5="","ADA",VLOOKUP(A5,'All float token'!A$2:B$64,2,FALSE)) -> BTC | F5: =IF(B5="","ADA",VLOOKUP(B5,'All float token'!A$2:B$64,2,FALSE)) -> ADA
A6: 25c5de5f5b286073c593edfd77b48abc7a48e5a4f3d4cd9d428ff935.55534443 | C6: 8000 | D6: TRUE | E6: =IF(A6="","ADA",VLOOKUP(A6,'All float token'!A$2:B$64,2,FALSE)) -> USDC | F6: =IF(B6="","ADA",VLOOKUP(B6,'All float token'!A$2:B$64,2,FALSE)) -> ADA
A7: 25c5de5f5b286073c593edfd77b48abc7a48e5a4f3d4cd9d428ff935.55534454 | C7: 8000 | D7: TRUE | E7: =IF(A7="","ADA",VLOOKUP(A7,'All float token'!A$2:B$64,2,FALSE)) -> USDT | F7: =IF(B7="","ADA",VLOOKUP(B7,'All float token'!A$2:B$64,2,FALSE)) -> ADA
A8: 4cf6a914372155ec78f6643141e280d38e3bae4ffbf623765efce3de.4254435f4144415f4c51 | C8: 8000 | D8: TRUE | E8: =IF(A8="","ADA",VLOOKUP(A8,'All float token'!A$2:B$64,2,FALSE)) -> [splLP]ADA.BTC.30 | F8: =IF(B8="","ADA",VLOOKUP(B8,'All float token'!A$2:B$64,2,FALSE)) -> ADA
A9: 6df63e2fdde8b2c3b3396265b0cc824aa4fb999396b1c154280f6b0c | C9: 8000 | D9: TRUE | E9: =IF(A9="","ADA",VLOOKUP(A9,'All float token'!A$2:B$64,2,FALSE)) -> qDJED | F9: =IF(B9="","ADA",VLOOKUP(B9,'All float token'!A$2:B$64,2,FALSE)) -> ADA
A10: 6ebaa7305f90791b9fae1c0bbbc9a3a1820088b621e95193df396772.4254435f4144415f4c51 | C10: 8000 | D10: TRUE | E10: =IF(A10="","ADA",VLOOKUP(A10,'All float token'!A$2:B$64,2,FALSE)) -> [splLP]ADA.BTC.50 | F10: =IF(B10="","ADA",VLOOKUP(B10,'All float token'!A$2:B$64,2,FALSE)) -> ADA
A11: 7a4d45e6b4e6835c4cea3968f291fab3704949cfd2f2dc1997c4eeec | C11: 8000 | D11: TRUE | E11: =IF(A11="","ADA",VLOOKUP(A11,'All float token'!A$2:B$64,2,FALSE)) -> qUSDT | F11: =IF(B11="","ADA",VLOOKUP(B11,'All float token'!A$2:B$64,2,FALSE)) -> ADA
A12: 7b7976222e874b1ac7c34fc5a56563203f7562fb217068242f7f5059.446a65644d6963726f5553445f4144415f4c51 | C12: 8000 | D12: TRUE | E12: =IF(A12="","ADA",VLOOKUP(A12,'All float token'!A$2:B$64,2,FALSE)) -> [splLP]ADA.DJED | F12: =IF(B12="","ADA",VLOOKUP(B12,'All float token'!A$2:B$64,2,FALSE)) -> ADA
A13: 8db269c3ec630e06ae29f74bc39edd1f87c819f1056206e879a1cd61.446a65644d6963726f555344 | C13: 8000 | D13: TRUE | E13: =IF(A13="","ADA",VLOOKUP(A13,'All float token'!A$2:B$64,2,FALSE)) -> DJED | F13: =IF(B13="","ADA",VLOOKUP(B13,'All float token'!A$2:B$64,2,FALSE)) -> ADA
... A33: fe7c786ab321f41c654ef6c1af7b3250a613c24e4213e0425a7ae456.55534441 | C33: 8000 | D33: TRUE | E33: =IF(A33="","ADA",VLOOKUP(A33,'All float token'!A$2:B$64,2,FALSE)) -> USDA | F33: =IF(B33="","ADA",VLOOKUP(B33,'All float token'!A$2:B$64,2,FALSE)) -> ADA
B34: c48cbb3d5e57ed56e276bc45f99ab39abe94e6cd7ac39fb402da47ad.0014df105553444d | C34: 8000 | D34: TRUE | E34: =IF(A34="","ADA",VLOOKUP(A34,'All float token'!A$2:B$64,2,FALSE)) -> ADA | F34: =IF(B34="","ADA",VLOOKUP(B34,'All float token'!A$2:B$64,2,FALSE)) -> USDM
A35: 09f4212b4f1c4a2d1300866e8decec795abb8eb8bbdc34d2d66384fd.555344545f4144415f4c51 | B35: c48cbb3d5e57ed56e276bc45f99ab39abe94e6cd7ac39fb402da47ad.0014df105553444d | C35: 8000 | D35: TRUE | E35: =IF(A35="","ADA",VLOOKUP(A35,'All float token'!A$2:B$64,2,FALSE)) -> [splLP]ADA.USDT | F35: =IF(B35="","ADA",VLOOKUP(B35,'All float token'!A$2:B$64,2,FALSE)) -> USDM
A36: 0a0a692605bed9e698a172a35adbdb70a04b40273c9043e1c4e4570a.0014efbfbd105553444d5f4144415f4c51 | B36: c48cbb3d5e57ed56e276bc45f99ab39abe94e6cd7ac39fb402da47ad.0014df105553444d | C36: 8000 | D36: TRUE | E36: =IF(A36="","ADA",VLOOKUP(A36,'All float token'!A$2:B$64,2,FALSE)) -> [splLP]ADA.USDM.500 | F36: =IF(B36="","ADA",VLOOKUP(B36,'All float token'!A$2:B$64,2,FALSE)) -> USDM
A37: 0d91892d31eef2398d66e771a03feea04ca17cd26655c2cc1550514a.555344415f4144415f4c51 | B37: c48cbb3d5e57ed56e276bc45f99ab39abe94e6cd7ac39fb402da47ad.0014df105553444d | C37: 8000 | D37: TRUE | E37: =IF(A37="","ADA",VLOOKUP(A37,'All float token'!A$2:B$64,2,FALSE)) -> [splLP]ADA.USDA | F37: =IF(B37="","ADA",VLOOKUP(B37,'All float token'!A$2:B$64,2,FALSE)) -> USDM
A38: 25c5de5f5b286073c593edfd77b48abc7a48e5a4f3d4cd9d428ff935.425443 | B38: c48cbb3d5e57ed56e276bc45f99ab39abe94e6cd7ac39fb402da47ad.0014df105553444d | C38: 8000 | D38: TRUE | E38: =IF(A38="","ADA",VLOOKUP(A38,'All float token'!A$2:B$64,2,FALSE)) -> BTC | F38: =IF(B38="","ADA",VLOOKUP(B38,'All float token'!A$2:B$64,2,FALSE)) -> USDM
A39: 25c5de5f5b286073c593edfd77b48abc7a48e5a4f3d4cd9d428ff935.55534443 | B39: c48cbb3d5e57ed56e276bc45f99ab39abe94e6cd7ac39fb402da47ad.0014df105553444d | C39: 9000 | D39: TRUE | E39: =IF(A39="","ADA",VLOOKUP(A39,'All float token'!A$2:B$64,2,FALSE)) -> USDC | F39: =IF(B39="","ADA",VLOOKUP(B39,'All float token'!A$2:B$64,2,FALSE)) -> USDM
A40: 25c5de5f5b286073c593edfd77b48abc7a48e5a4f3d4cd9d428ff935.55534454 | B40: c48cbb3d5e57ed56e276bc45f99ab39abe94e6cd7ac39fb402da47ad.0014df105553444d | C40: 9000 | D40: TRUE | E40: =IF(A40="","ADA",VLOOKUP(A40,'All float token'!A$2:B$64,2,FALSE)) -> USDT | F40: =IF(B40="","ADA",VLOOKUP(B40,'All float token'!A$2:B$64,2,FALSE)) -> USDM
A41: 4cf6a914372155ec78f6643141e280d38e3bae4ffbf623765efce3de.4254435f4144415f4c51 | B41: c48cbb3d5e57ed56e276bc45f99ab39abe94e6cd7ac39fb402da47ad.0014df105553444d | C41: 8000 | D41: TRUE | E41: =IF(A41="","ADA",VLOOKUP(A41,'All float token'!A$2:B$64,2,FALSE)) -> [splLP]ADA.BTC.30 | F41: =IF(B41="","ADA",VLOOKUP(B41,'All float token'!A$2:B$64,2,FALSE)) -> USDM
A42: 6df63e2fdde8b2c3b3396265b0cc824aa4fb999396b1c154280f6b0c | B42: c48cbb3d5e57ed56e276bc45f99ab39abe94e6cd7ac39fb402da47ad.0014df105553444d | C42: 9000 | D42: TRUE | E42: =IF(A42="","ADA",VLOOKUP(A42,'All float token'!A$2:B$64,2,FALSE)) -> qDJED | F42: =IF(B42="","ADA",VLOOKUP(B42,'All float token'!A$2:B$64,2,FALSE)) -> USDM
A43: 6ebaa7305f90791b9fae1c0bbbc9a3a1820088b621e95193df396772.4254435f4144415f4c51 | B43: c48cbb3d5e57ed56e276bc45f99ab39abe94e6cd7ac39fb402da47ad.0014df105553444d | C43: 8000 | D43: TRUE | E43: =IF(A43="","ADA",VLOOKUP(A43,'All float token'!A$2:B$64,2,FALSE)) -> [splLP]ADA.BTC.50 | F43: =IF(B43="","ADA",VLOOKUP(B43,'All float token'!A$2:B$64,2,FALSE)) -> USDM
A44: 7a4d45e6b4e6835c4cea3968f291fab3704949cfd2f2dc1997c4eeec | B44: c48cbb3d5e57ed56e276bc45f99ab39abe94e6cd7ac39fb402da47ad.0014df105553444d | C44: 9000 | D44: TRUE | E44: =IF(A44="","ADA",VLOOKUP(A44,'All float token'!A$2:B$64,2,FALSE)) -> qUSDT | F44: =IF(B44="","ADA",VLOOKUP(B44,'All float token'!A$2:B$64,2,FALSE)) -> USDM
A45: 7b7976222e874b1ac7c34fc5a56563203f7562fb217068242f7f5059.446a65644d6963726f5553445f4144415f4c51 | B45: c48cbb3d5e57ed56e276bc45f99ab39abe94e6cd7ac39fb402da47ad.0014df105553444d | C45: 8000 | D45: TRUE | E45: =IF(A45="","ADA",VLOOKUP(A45,'All float token'!A$2:B$64,2,FALSE)) -> [splLP]ADA.DJED | F45: =IF(B45="","ADA",VLOOKUP(B45,'All float token'!A$2:B$64,2,FALSE)) -> USDM
A46: 8db269c3ec630e06ae29f74bc39edd1f87c819f1056206e879a1cd61.446a65644d6963726f555344 | B46: c48cbb3d5e57ed56e276bc45f99ab39abe94e6cd7ac39fb402da47ad.0014df105553444d | C46: 9000 | D46: TRUE | E46: =IF(A46="","ADA",VLOOKUP(A46,'All float token'!A$2:B$64,2,FALSE)) -> DJED | F46: =IF(B46="","ADA",VLOOKUP(B46,'All float token'!A$2:B$64,2,FALSE)) -> USDM
... A65: fe7c786ab321f41c654ef6c1af7b3250a613c24e4213e0425a7ae456.55534441 | B65: c48cbb3d5e57ed56e276bc45f99ab39abe94e6cd7ac39fb402da47ad.0014df105553444d | C65: 9000 | D65: TRUE | E65: =IF(A65="","ADA",VLOOKUP(A65,'All float token'!A$2:B$64,2,FALSE)) -> USDA | F65: =IF(B65="","ADA",VLOOKUP(B65,'All float token'!A$2:B$64,2,FALSE)) -> USDM
B66: fe7c786ab321f41c654ef6c1af7b3250a613c24e4213e0425a7ae456.55534441 | C66: 8000 | D66: TRUE | E66: =IF(A66="","ADA",VLOOKUP(A66,'All float token'!A$2:B$64,2,FALSE)) -> ADA | F66: =IF(B66="","ADA",VLOOKUP(B66,'All float token'!A$2:B$64,2,FALSE)) -> USDA
A67: 09f4212b4f1c4a2d1300866e8decec795abb8eb8bbdc34d2d66384fd.555344545f4144415f4c51 | B67: fe7c786ab321f41c654ef6c1af7b3250a613c24e4213e0425a7ae456.55534441 | C67: 8000 | D67: TRUE | E67: =IF(A67="","ADA",VLOOKUP(A67,'All float token'!A$2:B$64,2,FALSE)) -> [splLP]ADA.USDT | F67: =IF(B67="","ADA",VLOOKUP(B67,'All float token'!A$2:B$64,2,FALSE)) -> USDA
A68: 0a0a692605bed9e698a172a35adbdb70a04b40273c9043e1c4e4570a.0014efbfbd105553444d5f4144415f4c51 | B68: fe7c786ab321f41c654ef6c1af7b3250a613c24e4213e0425a7ae456.55534441 | C68: 8000 | D68: TRUE | E68: =IF(A68="","ADA",VLOOKUP(A68,'All float token'!A$2:B$64,2,FALSE)) -> [splLP]ADA.USDM.500 | F68: =IF(B68="","ADA",VLOOKUP(B68,'All float token'!A$2:B$64,2,FALSE)) -> USDA
A69: 0d91892d31eef2398d66e771a03feea04ca17cd26655c2cc1550514a.555344415f4144415f4c51 | B69: fe7c786ab321f41c654ef6c1af7b3250a613c24e4213e0425a7ae456.55534441 | C69: 8000 | D69: TRUE | E69: =IF(A69="","ADA",VLOOKUP(A69,'All float token'!A$2:B$64,2,FALSE)) -> [splLP]ADA.USDA | F69: =IF(B69="","ADA",VLOOKUP(B69,'All float token'!A$2:B$64,2,FALSE)) -> USDA
A70: 25c5de5f5b286073c593edfd77b48abc7a48e5a4f3d4cd9d428ff935.425443 | B70: fe7c786ab321f41c654ef6c1af7b3250a613c24e4213e0425a7ae456.55534441 | C70: 8000 | D70: TRUE | E70: =IF(A70="","ADA",VLOOKUP(A70,'All float token'!A$2:B$64,2,FALSE)) -> BTC | F70: =IF(B70="","ADA",VLOOKUP(B70,'All float token'!A$2:B$64,2,FALSE)) -> USDA
A71: 25c5de5f5b286073c593edfd77b48abc7a48e5a4f3d4cd9d428ff935.55534443 | B71: fe7c786ab321f41c654ef6c1af7b3250a613c24e4213e0425a7ae456.55534441 | C71: 9000 | D71: TRUE | E71: =IF(A71="","ADA",VLOOKUP(A71,'All float token'!A$2:B$64,2,FALSE)) -> USDC | F71: =IF(B71="","ADA",VLOOKUP(B71,'All float token'!A$2:B$64,2,FALSE)) -> USDA
A72: 25c5de5f5b286073c593edfd77b48abc7a48e5a4f3d4cd9d428ff935.55534454 | B72: fe7c786ab321f41c654ef6c1af7b3250a613c24e4213e0425a7ae456.55534441 | C72: 9000 | D72: TRUE | E72: =IF(A72="","ADA",VLOOKUP(A72,'All float token'!A$2:B$64,2,FALSE)) -> USDT | F72: =IF(B72="","ADA",VLOOKUP(B72,'All float token'!A$2:B$64,2,FALSE)) -> USDA
A73: 4cf6a914372155ec78f6643141e280d38e3bae4ffbf623765efce3de.4254435f4144415f4c51 | B73: fe7c786ab321f41c654ef6c1af7b3250a613c24e4213e0425a7ae456.55534441 | C73: 8000 | D73: TRUE | E73: =IF(A73="","ADA",VLOOKUP(A73,'All float token'!A$2:B$64,2,FALSE)) -> [splLP]ADA.BTC.30 | F73: =IF(B73="","ADA",VLOOKUP(B73,'All float token'!A$2:B$64,2,FALSE)) -> USDA
A74: 6df63e2fdde8b2c3b3396265b0cc824aa4fb999396b1c154280f6b0c | B74: fe7c786ab321f41c654ef6c1af7b3250a613c24e4213e0425a7ae456.55534441 | C74: 9000 | D74: TRUE | E74: =IF(A74="","ADA",VLOOKUP(A74,'All float token'!A$2:B$64,2,FALSE)) -> qDJED | F74: =IF(B74="","ADA",VLOOKUP(B74,'All float token'!A$2:B$64,2,FALSE)) -> USDA
A75: 6ebaa7305f90791b9fae1c0bbbc9a3a1820088b621e95193df396772.4254435f4144415f4c51 | B75: fe7c786ab321f41c654ef6c1af7b3250a613c24e4213e0425a7ae456.55534441 | C75: 8000 | D75: TRUE | E75: =IF(A75="","ADA",VLOOKUP(A75,'All float token'!A$2:B$64,2,FALSE)) -> [splLP]ADA.BTC.50 | F75: =IF(B75="","ADA",VLOOKUP(B75,'All float token'!A$2:B$64,2,FALSE)) -> USDA
A76: 7a4d45e6b4e6835c4cea3968f291fab3704949cfd2f2dc1997c4eeec | B76: fe7c786ab321f41c654ef6c1af7b3250a613c24e4213e0425a7ae456.55534441 | C76: 9000 | D76: TRUE | E76: =IF(A76="","ADA",VLOOKUP(A76,'All float token'!A$2:B$64,2,FALSE)) -> qUSDT | F76: =IF(B76="","ADA",VLOOKUP(B76,'All float token'!A$2:B$64,2,FALSE)) -> USDA
A77: 7b7976222e874b1ac7c34fc5a56563203f7562fb217068242f7f5059.446a65644d6963726f5553445f4144415f4c51 | B77: fe7c786ab321f41c654ef6c1af7b3250a613c24e4213e0425a7ae456.55534441 | C77: 8000 | D77: TRUE | E77: =IF(A77="","ADA",VLOOKUP(A77,'All float token'!A$2:B$64,2,FALSE)) -> [splLP]ADA.DJED | F77: =IF(B77="","ADA",VLOOKUP(B77,'All float token'!A$2:B$64,2,FALSE)) -> USDA
...

Sheet Sheet3
A1: supply_token | B1: dtoken
B2: 94dca24a1f1fcc2ff51cd90f32f4fe9e786d861a2dbf7d27598d26e8.f04403181fbd051edd971af67b85f6c6fe1d9d98949a80b9f3803a14 | C2: =IF(A2="","ADA",VLOOKUP(A2,'All float token'!$A$2:$B$64,2,FALSE)) -> ADA | D2: =IF(B2="","ADA",VLOOKUP(B2,'All float token'!$A$2:$B$64,2,FALSE)) -> dADA
A3: 25c5de5f5b286073c593edfd77b48abc7a48e5a4f3d4cd9d428ff935.425443 | B3: 94dca24a1f1fcc2ff51cd90f32f4fe9e786d861a2dbf7d27598d26e8.134ab43b73bd6f5ae70534fe51194ad62618d39a539830ecef4f8e19 | C3: =IF(A3="","ADA",VLOOKUP(A3,'All float token'!$A$2:$B$64,2,FALSE)) -> BTC | D3: =IF(B3="","ADA",VLOOKUP(B3,'All float token'!$A$2:$B$64,2,FALSE)) -> dBTC
A4: 25c5de5f5b286073c593edfd77b48abc7a48e5a4f3d4cd9d428ff935.55534443 | B4: 94dca24a1f1fcc2ff51cd90f32f4fe9e786d861a2dbf7d27598d26e8.b96f6167426d625b8975c0437966745c9240e6488517b2b2f44bc7c7 | C4: =IF(A4="","ADA",VLOOKUP(A4,'All float token'!$A$2:$B$64,2,FALSE)) -> USDC | D4: =IF(B4="","ADA",VLOOKUP(B4,'All float token'!$A$2:$B$64,2,FALSE)) -> dUSDC
A5: 25c5de5f5b286073c593edfd77b48abc7a48e5a4f3d4cd9d428ff935.55534454 | B5: 94dca24a1f1fcc2ff51cd90f32f4fe9e786d861a2dbf7d27598d26e8.2d94b144d91520d0de771f6c3449d5cff8f0373c472dae2b9851a8c2 | C5: =IF(A5="","ADA",VLOOKUP(A5,'All float token'!$A$2:$B$64,2,FALSE)) -> USDT | D5: =IF(B5="","ADA",VLOOKUP(B5,'All float token'!$A$2:$B$64,2,FALSE)) -> dUSDT
A6: 279c909f348e533da5808898f87f9a14bb2c3dfbbacccd631d927a3f.534e454b | B6: 94dca24a1f1fcc2ff51cd90f32f4fe9e786d861a2dbf7d27598d26e8.2e614ed06d9ab2b693f108251c6df8d5e37cae81ffce99a4cf0a781f | C6: =IF(A6="","ADA",VLOOKUP(A6,'All float token'!$A$2:$B$64,2,FALSE)) -> Snek | D6: =IF(B6="","ADA",VLOOKUP(B6,'All float token'!$A$2:$B$64,2,FALSE)) -> dSNEK
A7: 2852268cf6e2db42e20f2fd3125f541e5d6c5a3d70b4dda17c2daa82 | B7: 94dca24a1f1fcc2ff51cd90f32f4fe9e786d861a2dbf7d27598d26e8.3cfdbb46c8359e7f5e56d48a330cf85fc38eef19c83730198bc0dcbb | C7: =IF(A7="","ADA",VLOOKUP(A7,'All float token'!$A$2:$B$64,2,FALSE)) -> The O Token | D7: =IF(B7="","ADA",VLOOKUP(B7,'All float token'!$A$2:$B$64,2,FALSE)) -> dO
A8: 29d222ce763455e3d7a09a665ce554f00ac89d2e99a1a83d267170c6.4d494e | B8: 94dca24a1f1fcc2ff51cd90f32f4fe9e786d861a2dbf7d27598d26e8.251d5ccb51543f3647b344d4a4c8f2df5bff9d164854e3e7fe4b1711 | C8: =IF(A8="","ADA",VLOOKUP(A8,'All float token'!$A$2:$B$64,2,FALSE)) -> Minswap | D8: =IF(B8="","ADA",VLOOKUP(B8,'All float token'!$A$2:$B$64,2,FALSE)) -> dMIN
A9: 2d9db8a89f074aa045eab177f23a3395f62ced8b53499a9e4ad46c80.464c4f57 | B9: 94dca24a1f1fcc2ff51cd90f32f4fe9e786d861a2dbf7d27598d26e8.18e8d03ef4d8ab3c408551378040ae6a8dd1bb437023858bf4994df7 | C9: =IF(A9="","ADA",VLOOKUP(A9,'All float token'!$A$2:$B$64,2,FALSE)) -> FLOW | D9: =IF(B9="","ADA",VLOOKUP(B9,'All float token'!$A$2:$B$64,2,FALSE)) -> dFLOW
A10: 533bb94a8850ee3ccbe483106489399112b74c905342cb1792a797a0.494e4459 | B10: 94dca24a1f1fcc2ff51cd90f32f4fe9e786d861a2dbf7d27598d26e8.a1bc0130b1eb217e58c2b40f4e6ed7647af5c71157466bd6a0dbb85c | C10: =IF(A10="","ADA",VLOOKUP(A10,'All float token'!$A$2:$B$64,2,FALSE)) -> Indigo DAO Token | D10: =IF(B10="","ADA",VLOOKUP(B10,'All float token'!$A$2:$B$64,2,FALSE)) -> dINDY
A11: 577f0b1342f8f8f4aed3388b80a8535812950c7a892495c0ecdf0f1e.0014df10464c4454 | B11: 94dca24a1f1fcc2ff51cd90f32f4fe9e786d861a2dbf7d27598d26e8.45af09272aeaf60d2215ce33daa6d2bc3ced61e5b59be434d21cd2e8 | C11: =IF(A11="","ADA",VLOOKUP(A11,'All float token'!$A$2:$B$64,2,FALSE)) -> FLDT | D11: =IF(B11="","ADA",VLOOKUP(B11,'All float token'!$A$2:$B$64,2,FALSE)) -> dFLDT
A12: 5d16cc1a177b5d9ba9cfa9793b07e60f1fb70fea1f8aef064415d114.494147 | B12: 94dca24a1f1fcc2ff51cd90f32f4fe9e786d861a2dbf7d27598d26e8.4c56da0af61dfca72b32de9fc0c44ecdd248932e69ce267d62b7ddc1 | C12: =IF(A12="","ADA",VLOOKUP(A12,'All float token'!$A$2:$B$64,2,FALSE)) -> IAGON | D12: =IF(B12="","ADA",VLOOKUP(B12,'All float token'!$A$2:$B$64,2,FALSE)) -> dIAG
A13: 5deab590a137066fef0e56f06ef1b830f21bc5d544661ba570bdd2ae.424f44454741 | B13: 94dca24a1f1fcc2ff51cd90f32f4fe9e786d861a2dbf7d27598d26e8.34d8725885174384ff7cd92e8b0b7a1d71a12550c9d61360ad4cf43c | C13: =IF(A13="","ADA",VLOOKUP(A13,'All float token'!$A$2:$B$64,2,FALSE)) -> BODEGA | D13: =IF(B13="","ADA",VLOOKUP(B13,'All float token'!$A$2:$B$64,2,FALSE)) -> dBODEGA
A14: 8db269c3ec630e06ae29f74bc39edd1f87c819f1056206e879a1cd61.446a65644d6963726f555344 | B14: 94dca24a1f1fcc2ff51cd90f32f4fe9e786d861a2dbf7d27598d26e8.a90873033a7449a360ab4a9b07b7262cad46a54031d09d784cf01127 | C14: =IF(A14="","ADA",VLOOKUP(A14,'All float token'!$A$2:$B$64,2,FALSE)) -> DJED | D14: =IF(B14="","ADA",VLOOKUP(B14,'All float token'!$A$2:$B$64,2,FALSE)) -> dDJED
... A21: fe7c786ab321f41c654ef6c1af7b3250a613c24e4213e0425a7ae456.55534441 | B21: 94dca24a1f1fcc2ff51cd90f32f4fe9e786d861a2dbf7d27598d26e8.7553c4258a557314d787908085e67fb50f7d6f8f6ff6e0d1c9b9306b | C21: =IF(A21="","ADA",VLOOKUP(A21,'All float token'!$A$2:$B$64,2,FALSE)) -> USDA | D21: =IF(B21="","ADA",VLOOKUP(B21,'All float token'!$A$2:$B$64,2,FALSE)) -> dUSDA

Sheet ListTokenPairs-1
A1: baseToken | B1: quoteToken | C1: base token name | D1: quote token name
A2: 09f4212b4f1c4a2d1300866e8decec795abb8eb8bbdc34d2d66384fd.555344545f4144415f4c51 | C2: =VLOOKUP(A2,'All float token'!A$2:B$64,2,FALSE) -> [splLP]ADA.USDT | D2: =VLOOKUP(B2,'All float token'!A$2:B$64,2,FALSE) -> #N/A
A3: 0a0a692605bed9e698a172a35adbdb70a04b40273c9043e1c4e4570a.0014efbfbd105553444d5f4144415f4c51 | C3: =VLOOKUP(A3,'All float token'!A$2:B$64,2,FALSE) -> [splLP]ADA.USDM.500 | D3: =VLOOKUP(B3,'All float token'!A$2:B$64,2,FALSE) -> #N/A
A4: 0d91892d31eef2398d66e771a03feea04ca17cd26655c2cc1550514a.555344415f4144415f4c51 | C4: =VLOOKUP(A4,'All float token'!A$2:B$64,2,FALSE) -> [splLP]ADA.USDA | D4: =VLOOKUP(B4,'All float token'!A$2:B$64,2,FALSE) -> #N/A
A5: 25c5de5f5b286073c593edfd77b48abc7a48e5a4f3d4cd9d428ff935.425443 | C5: =VLOOKUP(A5,'All float token'!A$2:B$64,2,FALSE) -> BTC | D5: =VLOOKUP(B5,'All float token'!A$2:B$64,2,FALSE) -> #N/A
A6: 25c5de5f5b286073c593edfd77b48abc7a48e5a4f3d4cd9d428ff935.55534443 | C6: =VLOOKUP(A6,'All float token'!A$2:B$64,2,FALSE) -> USDC | D6: =VLOOKUP(B6,'All float token'!A$2:B$64,2,FALSE) -> #N/A
A7: 25c5de5f5b286073c593edfd77b48abc7a48e5a4f3d4cd9d428ff935.55534454 | C7: =VLOOKUP(A7,'All float token'!A$2:B$64,2,FALSE) -> USDT | D7: =VLOOKUP(B7,'All float token'!A$2:B$64,2,FALSE) -> #N/A
A8: 4cf6a914372155ec78f6643141e280d38e3bae4ffbf623765efce3de.4254435f4144415f4c51 | C8: =VLOOKUP(A8,'All float token'!A$2:B$64,2,FALSE) -> [splLP]ADA.BTC.30 | D8: =VLOOKUP(B8,'All float token'!A$2:B$64,2,FALSE) -> #N/A
A9: 6df63e2fdde8b2c3b3396265b0cc824aa4fb999396b1c154280f6b0c | C9: =VLOOKUP(A9,'All float token'!A$2:B$64,2,FALSE) -> qDJED | D9: =VLOOKUP(B9,'All float token'!A$2:B$64,2,FALSE) -> #N/A
A10: 6ebaa7305f90791b9fae1c0bbbc9a3a1820088b621e95193df396772.4254435f4144415f4c51 | C10: =VLOOKUP(A10,'All float token'!A$2:B$64,2,FALSE) -> [splLP]ADA.BTC.50 | D10: =VLOOKUP(B10,'All float token'!A$2:B$64,2,FALSE) -> #N/A
A11: 7a4d45e6b4e6835c4cea3968f291fab3704949cfd2f2dc1997c4eeec | C11: =VLOOKUP(A11,'All float token'!A$2:B$64,2,FALSE) -> qUSDT | D11: =VLOOKUP(B11,'All float token'!A$2:B$64,2,FALSE) -> #N/A
A12: 7b7976222e874b1ac7c34fc5a56563203f7562fb217068242f7f5059.446a65644d6963726f5553445f4144415f4c51 | C12: =VLOOKUP(A12,'All float token'!A$2:B$64,2,FALSE) -> [splLP]ADA.DJED | D12: =VLOOKUP(B12,'All float token'!A$2:B$64,2,FALSE) -> #N/A
A13: 8db269c3ec630e06ae29f74bc39edd1f87c819f1056206e879a1cd61.446a65644d6963726f555344 | C13: =VLOOKUP(A13,'All float token'!A$2:B$64,2,FALSE) -> DJED | D13: =VLOOKUP(B13,'All float token'!A$2:B$64,2,FALSE) -> #N/A
... A33: fe7c786ab321f41c654ef6c1af7b3250a613c24e4213e0425a7ae456.55534441 | C33: =VLOOKUP(A33,'All float token'!A$2:B$64,2,FALSE) -> USDA | D33: =VLOOKUP(B33,'All float token'!A$2:B$64,2,FALSE) -> #N/A
B34: c48cbb3d5e57ed56e276bc45f99ab39abe94e6cd7ac39fb402da47ad.0014df105553444d | C34: =VLOOKUP(A34,'All float token'!A$2:B$64,2,FALSE) -> #N/A | D34: =VLOOKUP(B34,'All float token'!A$2:B$64,2,FALSE) -> USDM
A35: 09f4212b4f1c4a2d1300866e8decec795abb8eb8bbdc34d2d66384fd.555344545f4144415f4c51 | B35: c48cbb3d5e57ed56e276bc45f99ab39abe94e6cd7ac39fb402da47ad.0014df105553444d | C35: =VLOOKUP(A35,'All float token'!A$2:B$64,2,FALSE) -> [splLP]ADA.USDT | D35: =VLOOKUP(B35,'All float token'!A$2:B$64,2,FALSE) -> USDM
A36: 0a0a692605bed9e698a172a35adbdb70a04b40273c9043e1c4e4570a.0014efbfbd105553444d5f4144415f4c51 | B36: c48cbb3d5e57ed56e276bc45f99ab39abe94e6cd7ac39fb402da47ad.0014df105553444d | C36: =VLOOKUP(A36,'All float token'!A$2:B$64,2,FALSE) -> [splLP]ADA.USDM.500 | D36: =VLOOKUP(B36,'All float token'!A$2:B$64,2,FALSE) -> USDM
A37: 0d91892d31eef2398d66e771a03feea04ca17cd26655c2cc1550514a.555344415f4144415f4c51 | B37: c48cbb3d5e57ed56e276bc45f99ab39abe94e6cd7ac39fb402da47ad.0014df105553444d | C37: =VLOOKUP(A37,'All float token'!A$2:B$64,2,FALSE) -> [splLP]ADA.USDA | D37: =VLOOKUP(B37,'All float token'!A$2:B$64,2,FALSE) -> USDM
A38: 25c5de5f5b286073c593edfd77b48abc7a48e5a4f3d4cd9d428ff935.425443 | B38: c48cbb3d5e57ed56e276bc45f99ab39abe94e6cd7ac39fb402da47ad.0014df105553444d | C38: =VLOOKUP(A38,'All float token'!A$2:B$64,2,FALSE) -> BTC | D38: =VLOOKUP(B38,'All float token'!A$2:B$64,2,FALSE) -> USDM
A39: 25c5de5f5b286073c593edfd77b48abc7a48e5a4f3d4cd9d428ff935.55534443 | B39: c48cbb3d5e57ed56e276bc45f99ab39abe94e6cd7ac39fb402da47ad.0014df105553444d | C39: =VLOOKUP(A39,'All float token'!A$2:B$64,2,FALSE) -> USDC | D39: =VLOOKUP(B39,'All float token'!A$2:B$64,2,FALSE) -> USDM
A40: 25c5de5f5b286073c593edfd77b48abc7a48e5a4f3d4cd9d428ff935.55534454 | B40: c48cbb3d5e57ed56e276bc45f99ab39abe94e6cd7ac39fb402da47ad.0014df105553444d | C40: =VLOOKUP(A40,'All float token'!A$2:B$64,2,FALSE) -> USDT | D40: =VLOOKUP(B40,'All float token'!A$2:B$64,2,FALSE) -> USDM
A41: 4cf6a914372155ec78f6643141e280d38e3bae4ffbf623765efce3de.4254435f4144415f4c51 | B41: c48cbb3d5e57ed56e276bc45f99ab39abe94e6cd7ac39fb402da47ad.0014df105553444d | C41: =VLOOKUP(A41,'All float token'!A$2:B$64,2,FALSE) -> [splLP]ADA.BTC.30 | D41: =VLOOKUP(B41,'All float token'!A$2:B$64,2,FALSE) -> USDM
A42: 6df63e2fdde8b2c3b3396265b0cc824aa4fb999396b1c154280f6b0c | B42: c48cbb3d5e57ed56e276bc45f99ab39abe94e6cd7ac39fb402da47ad.0014df105553444d | C42: =VLOOKUP(A42,'All float token'!A$2:B$64,2,FALSE) -> qDJED | D42: =VLOOKUP(B42,'All float token'!A$2:B$64,2,FALSE) -> USDM
A43: 6ebaa7305f90791b9fae1c0bbbc9a3a1820088b621e95193df396772.4254435f4144415f4c51 | B43: c48cbb3d5e57ed56e276bc45f99ab39abe94e6cd7ac39fb402da47ad.0014df105553444d | C43: =VLOOKUP(A43,'All float token'!A$2:B$64,2,FALSE) -> [splLP]ADA.BTC.50 | D43: =VLOOKUP(B43,'All float token'!A$2:B$64,2,FALSE) -> USDM
A44: 7a4d45e6b4e6835c4cea3968f291fab3704949cfd2f2dc1997c4eeec | B44: c48cbb3d5e57ed56e276bc45f99ab39abe94e6cd7ac39fb402da47ad.0014df105553444d | C44: =VLOOKUP(A44,'All float token'!A$2:B$64,2,FALSE) -> qUSDT | D44: =VLOOKUP(B44,'All float token'!A$2:B$64,2,FALSE) -> USDM
A45: 7b7976222e874b1ac7c34fc5a56563203f7562fb217068242f7f5059.446a65644d6963726f5553445f4144415f4c51 | B45: c48cbb3d5e57ed56e276bc45f99ab39abe94e6cd7ac39fb402da47ad.0014df105553444d | C45: =VLOOKUP(A45,'All float token'!A$2:B$64,2,FALSE) -> [splLP]ADA.DJED | D45: =VLOOKUP(B45,'All float token'!A$2:B$64,2,FALSE) -> USDM
A46: 8db269c3ec630e06ae29f74bc39edd1f87c819f1056206e879a1cd61.446a65644d6963726f555344 | B46: c48cbb3d5e57ed56e276bc45f99ab39abe94e6cd7ac39fb402da47ad.0014df105553444d | C46: =VLOOKUP(A46,'All float token'!A$2:B$64,2,FALSE) -> DJED | D46: =VLOOKUP(B46,'All float token'!A$2:B$64,2,FALSE) -> USDM
... A65: fe7c786ab321f41c654ef6c1af7b3250a613c24e4213e0425a7ae456.55534441 | B65: c48cbb3d5e57ed56e276bc45f99ab39abe94e6cd7ac39fb402da47ad.0014df105553444d | C65: =VLOOKUP(A65,'All float token'!A$2:B$64,2,FALSE) -> USDA | D65: =VLOOKUP(B65,'All float token'!A$2:B$64,2,FALSE) -> USDM
B66: fe7c786ab321f41c654ef6c1af7b3250a613c24e4213e0425a7ae456.55534441 | C66: =VLOOKUP(A66,'All float token'!A$2:B$64,2,FALSE) -> #N/A | D66: =VLOOKUP(B66,'All float token'!A$2:B$64,2,FALSE) -> USDA
A67: 09f4212b4f1c4a2d1300866e8decec795abb8eb8bbdc34d2d66384fd.555344545f4144415f4c51 | B67: fe7c786ab321f41c654ef6c1af7b3250a613c24e4213e0425a7ae456.55534441 | C67: =VLOOKUP(A67,'All float token'!A$2:B$64,2,FALSE) -> [splLP]ADA.USDT | D67: =VLOOKUP(B67,'All float token'!A$2:B$64,2,FALSE) -> USDA
A68: 0a0a692605bed9e698a172a35adbdb70a04b40273c9043e1c4e4570a.0014efbfbd105553444d5f4144415f4c51 | B68: fe7c786ab321f41c654ef6c1af7b3250a613c24e4213e0425a7ae456.55534441 | C68: =VLOOKUP(A68,'All float token'!A$2:B$64,2,FALSE) -> [splLP]ADA.USDM.500 | D68: =VLOOKUP(B68,'All float token'!A$2:B$64,2,FALSE) -> USDA
A69: 0d91892d31eef2398d66e771a03feea04ca17cd26655c2cc1550514a.555344415f4144415f4c51 | B69: fe7c786ab321f41c654ef6c1af7b3250a613c24e4213e0425a7ae456.55534441 | C69: =VLOOKUP(A69,'All float token'!A$2:B$64,2,FALSE) -> [splLP]ADA.USDA | D69: =VLOOKUP(B69,'All float token'!A$2:B$64,2,FALSE) -> USDA
A70: 25c5de5f5b286073c593edfd77b48abc7a48e5a4f3d4cd9d428ff935.425443 | B70: fe7c786ab321f41c654ef6c1af7b3250a613c24e4213e0425a7ae456.55534441 | C70: =VLOOKUP(A70,'All float token'!A$2:B$64,2,FALSE) -> BTC | D70: =VLOOKUP(B70,'All float token'!A$2:B$64,2,FALSE) -> USDA
A71: 25c5de5f5b286073c593edfd77b48abc7a48e5a4f3d4cd9d428ff935.55534443 | B71: fe7c786ab321f41c654ef6c1af7b3250a613c24e4213e0425a7ae456.55534441 | C71: =VLOOKUP(A71,'All float token'!A$2:B$64,2,FALSE) -> USDC | D71: =VLOOKUP(B71,'All float token'!A$2:B$64,2,FALSE) -> USDA
A72: 25c5de5f5b286073c593edfd77b48abc7a48e5a4f3d4cd9d428ff935.55534454 | B72: fe7c786ab321f41c654ef6c1af7b3250a613c24e4213e0425a7ae456.55534441 | C72: =VLOOKUP(A72,'All float token'!A$2:B$64,2,FALSE) -> USDT | D72: =VLOOKUP(B72,'All float token'!A$2:B$64,2,FALSE) -> USDA
A73: 4cf6a914372155ec78f6643141e280d38e3bae4ffbf623765efce3de.4254435f4144415f4c51 | B73: fe7c786ab321f41c654ef6c1af7b3250a613c24e4213e0425a7ae456.55534441 | C73: =VLOOKUP(A73,'All float token'!A$2:B$64,2,FALSE) -> [splLP]ADA.BTC.30 | D73: =VLOOKUP(B73,'All float token'!A$2:B$64,2,FALSE) -> USDA
A74: 6df63e2fdde8b2c3b3396265b0cc824aa4fb999396b1c154280f6b0c | B74: fe7c786ab321f41c654ef6c1af7b3250a613c24e4213e0425a7ae456.55534441 | C74: =VLOOKUP(A74,'All float token'!A$2:B$64,2,FALSE) -> qDJED | D74: =VLOOKUP(B74,'All float token'!A$2:B$64,2,FALSE) -> USDA
A75: 6ebaa7305f90791b9fae1c0bbbc9a3a1820088b621e95193df396772.4254435f4144415f4c51 | B75: fe7c786ab321f41c654ef6c1af7b3250a613c24e4213e0425a7ae456.55534441 | C75: =VLOOKUP(A75,'All float token'!A$2:B$64,2,FALSE) -> [splLP]ADA.BTC.50 | D75: =VLOOKUP(B75,'All float token'!A$2:B$64,2,FALSE) -> USDA
A76: 7a4d45e6b4e6835c4cea3968f291fab3704949cfd2f2dc1997c4eeec | B76: fe7c786ab321f41c654ef6c1af7b3250a613c24e4213e0425a7ae456.55534441 | C76: =VLOOKUP(A76,'All float token'!A$2:B$64,2,FALSE) -> qUSDT | D76: =VLOOKUP(B76,'All float token'!A$2:B$64,2,FALSE) -> USDA
A77: 7b7976222e874b1ac7c34fc5a56563203f7562fb217068242f7f5059.446a65644d6963726f5553445f4144415f4c51 | B77: fe7c786ab321f41c654ef6c1af7b3250a613c24e4213e0425a7ae456.55534441 | C77: =VLOOKUP(A77,'All float token'!A$2:B$64,2,FALSE) -> [splLP]ADA.DJED | D77: =VLOOKUP(B77,'All float token'!A$2:B$64,2,FALSE) -> USDA
...

Sheet ListTokenPairs-2
A1: baseToken | B1: quoteToken | C1: threshold | D1: isActive | E1: base token name | F1: quote token name
B2: 279c909f348e533da5808898f87f9a14bb2c3dfbbacccd631d927a3f.534e454b | C2: 8000 | D2: TRUE | E2: =IF(A2="","ADA",VLOOKUP(A2,'All float token'!A$2:B$64,2,FALSE)) -> ADA | F2: =IF(B2="","ADA",VLOOKUP(B2,'All float token'!A$2:B$64,2,FALSE)) -> Snek
A3: 09f4212b4f1c4a2d1300866e8decec795abb8eb8bbdc34d2d66384fd.555344545f4144415f4c51 | B3: 279c909f348e533da5808898f87f9a14bb2c3dfbbacccd631d927a3f.534e454b | C3: 8000 | D3: TRUE | E3: =IF(A3="","ADA",VLOOKUP(A3,'All float token'!A$2:B$64,2,FALSE)) -> [splLP]ADA.USDT | F3: =IF(B3="","ADA",VLOOKUP(B3,'All float token'!A$2:B$64,2,FALSE)) -> Snek
A4: 0a0a692605bed9e698a172a35adbdb70a04b40273c9043e1c4e4570a.0014efbfbd105553444d5f4144415f4c51 | B4: 279c909f348e533da5808898f87f9a14bb2c3dfbbacccd631d927a3f.534e454b | C4: 8000 | D4: TRUE | E4: =IF(A4="","ADA",VLOOKUP(A4,'All float token'!A$2:B$64,2,FALSE)) -> [splLP]ADA.USDM.500 | F4: =IF(B4="","ADA",VLOOKUP(B4,'All float token'!A$2:B$64,2,FALSE)) -> Snek
A5: 0d91892d31eef2398d66e771a03feea04ca17cd26655c2cc1550514a.555344415f4144415f4c51 | B5: 279c909f348e533da5808898f87f9a14bb2c3dfbbacccd631d927a3f.534e454b | C5: 8000 | D5: TRUE | E5: =IF(A5="","ADA",VLOOKUP(A5,'All float token'!A$2:B$64,2,FALSE)) -> [splLP]ADA.USDA | F5: =IF(B5="","ADA",VLOOKUP(B5,'All float token'!A$2:B$64,2,FALSE)) -> Snek
A6: 25c5de5f5b286073c593edfd77b48abc7a48e5a4f3d4cd9d428ff935.425443 | B6: 279c909f348e533da5808898f87f9a14bb2c3dfbbacccd631d927a3f.534e454b | C6: 8000 | D6: TRUE | E6: =IF(A6="","ADA",VLOOKUP(A6,'All float token'!A$2:B$64,2,FALSE)) -> BTC | F6: =IF(B6="","ADA",VLOOKUP(B6,'All float token'!A$2:B$64,2,FALSE)) -> Snek
A7: 25c5de5f5b286073c593edfd77b48abc7a48e5a4f3d4cd9d428ff935.55534443 | B7: 279c909f348e533da5808898f87f9a14bb2c3dfbbacccd631d927a3f.534e454b | C7: 8000 | D7: TRUE | E7: =IF(A7="","ADA",VLOOKUP(A7,'All float token'!A$2:B$64,2,FALSE)) -> USDC | F7: =IF(B7="","ADA",VLOOKUP(B7,'All float token'!A$2:B$64,2,FALSE)) -> Snek
A8: 25c5de5f5b286073c593edfd77b48abc7a48e5a4f3d4cd9d428ff935.55534454 | B8: 279c909f348e533da5808898f87f9a14bb2c3dfbbacccd631d927a3f.534e454b | C8: 8000 | D8: TRUE | E8: =IF(A8="","ADA",VLOOKUP(A8,'All float token'!A$2:B$64,2,FALSE)) -> USDT | F8: =IF(B8="","ADA",VLOOKUP(B8,'All float token'!A$2:B$64,2,FALSE)) -> Snek
A9: 2852268cf6e2db42e20f2fd3125f541e5d6c5a3d70b4dda17c2daa82 | B9: 279c909f348e533da5808898f87f9a14bb2c3dfbbacccd631d927a3f.534e454b | C9: 6000 | D9: TRUE | E9: =IF(A9="","ADA",VLOOKUP(A9,'All float token'!A$2:B$64,2,FALSE)) -> The O Token | F9: =IF(B9="","ADA",VLOOKUP(B9,'All float token'!A$2:B$64,2,FALSE)) -> Snek
A10: 29d222ce763455e3d7a09a665ce554f00ac89d2e99a1a83d267170c6.4d494e | B10: 279c909f348e533da5808898f87f9a14bb2c3dfbbacccd631d927a3f.534e454b | C10: 6000 | D10: TRUE | E10: =IF(A10="","ADA",VLOOKUP(A10,'All float token'!A$2:B$64,2,FALSE)) -> Minswap | F10: =IF(B10="","ADA",VLOOKUP(B10,'All float token'!A$2:B$64,2,FALSE)) -> Snek
A11: 2d9db8a89f074aa045eab177f23a3395f62ced8b53499a9e4ad46c80.464c4f57 | B11: 279c909f348e533da5808898f87f9a14bb2c3dfbbacccd631d927a3f.534e454b | C11: 6000 | D11: TRUE | E11: =IF(A11="","ADA",VLOOKUP(A11,'All float token'!A$2:B$64,2,FALSE)) -> FLOW | F11: =IF(B11="","ADA",VLOOKUP(B11,'All float token'!A$2:B$64,2,FALSE)) -> Snek
A12: 4cf6a914372155ec78f6643141e280d38e3bae4ffbf623765efce3de.4254435f4144415f4c51 | B12: 279c909f348e533da5808898f87f9a14bb2c3dfbbacccd631d927a3f.534e454b | C12: 8000 | D12: TRUE | E12: =IF(A12="","ADA",VLOOKUP(A12,'All float token'!A$2:B$64,2,FALSE)) -> [splLP]ADA.BTC.30 | F12: =IF(B12="","ADA",VLOOKUP(B12,'All float token'!A$2:B$64,2,FALSE)) -> Snek
A13: 533bb94a8850ee3ccbe483106489399112b74c905342cb1792a797a0.494e4459 | B13: 279c909f348e533da5808898f87f9a14bb2c3dfbbacccd631d927a3f.534e454b | C13: 6000 | D13: TRUE | E13: =IF(A13="","ADA",VLOOKUP(A13,'All float token'!A$2:B$64,2,FALSE)) -> Indigo DAO Token | F13: =IF(B13="","ADA",VLOOKUP(B13,'All float token'!A$2:B$64,2,FALSE)) -> Snek
A14: 577f0b1342f8f8f4aed3388b80a8535812950c7a892495c0ecdf0f1e.0014df10464c4454 | B14: 279c909f348e533da5808898f87f9a14bb2c3dfbbacccd631d927a3f.534e454b | C14: 6000 | D14: TRUE | E14: =IF(A14="","ADA",VLOOKUP(A14,'All float token'!A$2:B$64,2,FALSE)) -> FLDT | F14: =IF(B14="","ADA",VLOOKUP(B14,'All float token'!A$2:B$64,2,FALSE)) -> Snek
... A61: fe7c786ab321f41c654ef6c1af7b3250a613c24e4213e0425a7ae456.55534441 | B61: 279c909f348e533da5808898f87f9a14bb2c3dfbbacccd631d927a3f.534e454b | C61: 8000 | D61: TRUE | E61: =IF(A61="","ADA",VLOOKUP(A61,'All float token'!A$2:B$64,2,FALSE)) -> USDA | F61: =IF(B61="","ADA",VLOOKUP(B61,'All float token'!A$2:B$64,2,FALSE)) -> Snek
B62: f13ac4d66b3ee19a6aa0f2a22298737bd907cc95121662fc971b5275.535452494b45 | C62: 8000 | D62: TRUE | E62: =IF(A62="","ADA",VLOOKUP(A62,'All float token'!A$2:B$64,2,FALSE)) -> ADA | F62: =IF(B62="","ADA",VLOOKUP(B62,'All float token'!A$2:B$64,2,FALSE)) -> STRIKE
A63: 09f4212b4f1c4a2d1300866e8decec795abb8eb8bbdc34d2d66384fd.555344545f4144415f4c51 | B63: f13ac4d66b3ee19a6aa0f2a22298737bd907cc95121662fc971b5275.535452494b45 | C63: 8000 | D63: TRUE | E63: =IF(A63="","ADA",VLOOKUP(A63,'All float token'!A$2:B$64,2,FALSE)) -> [splLP]ADA.USDT | F63: =IF(B63="","ADA",VLOOKUP(B63,'All float token'!A$2:B$64,2,FALSE)) -> STRIKE
A64: 0a0a692605bed9e698a172a35adbdb70a04b40273c9043e1c4e4570a.0014efbfbd105553444d5f4144415f4c51 | B64: f13ac4d66b3ee19a6aa0f2a22298737bd907cc95121662fc971b5275.535452494b45 | C64: 8000 | D64: TRUE | E64: =IF(A64="","ADA",VLOOKUP(A64,'All float token'!A$2:B$64,2,FALSE)) -> [splLP]ADA.USDM.500 | F64: =IF(B64="","ADA",VLOOKUP(B64,'All float token'!A$2:B$64,2,FALSE)) -> STRIKE
A65: 0d91892d31eef2398d66e771a03feea04ca17cd26655c2cc1550514a.555344415f4144415f4c51 | B65: f13ac4d66b3ee19a6aa0f2a22298737bd907cc95121662fc971b5275.535452494b45 | C65: 8000 | D65: TRUE | E65: =IF(A65="","ADA",VLOOKUP(A65,'All float token'!A$2:B$64,2,FALSE)) -> [splLP]ADA.USDA | F65: =IF(B65="","ADA",VLOOKUP(B65,'All float token'!A$2:B$64,2,FALSE)) -> STRIKE
A66: 25c5de5f5b286073c593edfd77b48abc7a48e5a4f3d4cd9d428ff935.425443 | B66: f13ac4d66b3ee19a6aa0f2a22298737bd907cc95121662fc971b5275.535452494b45 | C66: 8000 | D66: TRUE | E66: =IF(A66="","ADA",VLOOKUP(A66,'All float token'!A$2:B$64,2,FALSE)) -> BTC | F66: =IF(B66="","ADA",VLOOKUP(B66,'All float token'!A$2:B$64,2,FALSE)) -> STRIKE
A67: 25c5de5f5b286073c593edfd77b48abc7a48e5a4f3d4cd9d428ff935.55534443 | B67: f13ac4d66b3ee19a6aa0f2a22298737bd907cc95121662fc971b5275.535452494b45 | C67: 8000 | D67: TRUE | E67: =IF(A67="","ADA",VLOOKUP(A67,'All float token'!A$2:B$64,2,FALSE)) -> USDC | F67: =IF(B67="","ADA",VLOOKUP(B67,'All float token'!A$2:B$64,2,FALSE)) -> STRIKE
A68: 25c5de5f5b286073c593edfd77b48abc7a48e5a4f3d4cd9d428ff935.55534454 | B68: f13ac4d66b3ee19a6aa0f2a22298737bd907cc95121662fc971b5275.535452494b45 | C68: 8000 | D68: TRUE | E68: =IF(A68="","ADA",VLOOKUP(A68,'All float token'!A$2:B$64,2,FALSE)) -> USDT | F68: =IF(B68="","ADA",VLOOKUP(B68,'All float token'!A$2:B$64,2,FALSE)) -> STRIKE
A69: 279c909f348e533da5808898f87f9a14bb2c3dfbbacccd631d927a3f.534e454b | B69: f13ac4d66b3ee19a6aa0f2a22298737bd907cc95121662fc971b5275.535452494b45 | C69: 6000 | D69: TRUE | E69: =IF(A69="","ADA",VLOOKUP(A69,'All float token'!A$2:B$64,2,FALSE)) -> Snek | F69: =IF(B69="","ADA",VLOOKUP(B69,'All float token'!A$2:B$64,2,FALSE)) -> STRIKE
A70: 2852268cf6e2db42e20f2fd3125f541e5d6c5a3d70b4dda17c2daa82 | B70: f13ac4d66b3ee19a6aa0f2a22298737bd907cc95121662fc971b5275.535452494b45 | C70: 6000 | D70: TRUE | E70: =IF(A70="","ADA",VLOOKUP(A70,'All float token'!A$2:B$64,2,FALSE)) -> The O Token | F70: =IF(B70="","ADA",VLOOKUP(B70,'All float token'!A$2:B$64,2,FALSE)) -> STRIKE
A71: 29d222ce763455e3d7a09a665ce554f00ac89d2e99a1a83d267170c6.4d494e | B71: f13ac4d66b3ee19a6aa0f2a22298737bd907cc95121662fc971b5275.535452494b45 | C71: 6000 | D71: TRUE | E71: =IF(A71="","ADA",VLOOKUP(A71,'All float token'!A$2:B$64,2,FALSE)) -> Minswap | F71: =IF(B71="","ADA",VLOOKUP(B71,'All float token'!A$2:B$64,2,FALSE)) -> STRIKE
A72: 2d9db8a89f074aa045eab177f23a3395f62ced8b53499a9e4ad46c80.464c4f57 | B72: f13ac4d66b3ee19a6aa0f2a22298737bd907cc95121662fc971b5275.535452494b45 | C72: 6000 | D72: TRUE | E72: =IF(A72="","ADA",VLOOKUP(A72,'All float token'!A$2:B$64,2,FALSE)) -> FLOW | F72: =IF(B72="","ADA",VLOOKUP(B72,'All float token'!A$2:B$64,2,FALSE)) -> STRIKE
A73: 4cf6a914372155ec78f6643141e280d38e3bae4ffbf623765efce3de.4254435f4144415f4c51 | B73: f13ac4d66b3ee19a6aa0f2a22298737bd907cc95121662fc971b5275.535452494b45 | C73: 8000 | D73: TRUE | E73: =IF(A73="","ADA",VLOOKUP(A73,'All float token'!A$2:B$64,2,FALSE)) -> [splLP]ADA.BTC.30 | F73: =IF(B73="","ADA",VLOOKUP(B73,'All float token'!A$2:B$64,2,FALSE)) -> STRIKE
A74: 533bb94a8850ee3ccbe483106489399112b74c905342cb1792a797a0.494e4459 | B74: f13ac4d66b3ee19a6aa0f2a22298737bd907cc95121662fc971b5275.535452494b45 | C74: 6000 | D74: TRUE | E74: =IF(A74="","ADA",VLOOKUP(A74,'All float token'!A$2:B$64,2,FALSE)) -> Indigo DAO Token | F74: =IF(B74="","ADA",VLOOKUP(B74,'All float token'!A$2:B$64,2,FALSE)) -> STRIKE
... A121: fe7c786ab321f41c654ef6c1af7b3250a613c24e4213e0425a7ae456.55534441 | B121: f13ac4d66b3ee19a6aa0f2a22298737bd907cc95121662fc971b5275.535452494b45 | C121: 8000 | D121: TRUE | E121: =IF(A121="","ADA",VLOOKUP(A121,'All float token'!A$2:B$64,2,FALSE)) -> USDA | F121: =IF(B121="","ADA",VLOOKUP(B121,'All float token'!A$2:B$64,2,FALSE)) -> STRIKE
B122: 5d16cc1a177b5d9ba9cfa9793b07e60f1fb70fea1f8aef064415d114.494147 | C122: 8000 | D122: TRUE | E122: =IF(A122="","ADA",VLOOKUP(A122,'All float token'!A$2:B$64,2,FALSE)) -> ADA | F122: =IF(B122="","ADA",VLOOKUP(B122,'All float token'!A$2:B$64,2,FALSE)) -> IAGON
A123: 09f4212b4f1c4a2d1300866e8decec795abb8eb8bbdc34d2d66384fd.555344545f4144415f4c51 | B123: 5d16cc1a177b5d9ba9cfa9793b07e60f1fb70fea1f8aef064415d114.494147 | C123: 8000 | D123: TRUE | E123: =IF(A123="","ADA",VLOOKUP(A123,'All float token'!A$2:B$64,2,FALSE)) -> [splLP]ADA.USDT | F123: =IF(B123="","ADA",VLOOKUP(B123,'All float token'!A$2:B$64,2,FALSE)) -> IAGON
A124: 0a0a692605bed9e698a172a35adbdb70a04b40273c9043e1c4e4570a.0014efbfbd105553444d5f4144415f4c51 | B124: 5d16cc1a177b5d9ba9cfa9793b07e60f1fb70fea1f8aef064415d114.494147 | C124: 8000 | D124: TRUE | E124: =IF(A124="","ADA",VLOOKUP(A124,'All float token'!A$2:B$64,2,FALSE)) -> [splLP]ADA.USDM.500 | F124: =IF(B124="","ADA",VLOOKUP(B124,'All float token'!A$2:B$64,2,FALSE)) -> IAGON
A125: 0d91892d31eef2398d66e771a03feea04ca17cd26655c2cc1550514a.555344415f4144415f4c51 | B125: 5d16cc1a177b5d9ba9cfa9793b07e60f1fb70fea1f8aef064415d114.494147 | C125: 8000 | D125: TRUE | E125: =IF(A125="","ADA",VLOOKUP(A125,'All float token'!A$2:B$64,2,FALSE)) -> [splLP]ADA.USDA | F125: =IF(B125="","ADA",VLOOKUP(B125,'All float token'!A$2:B$64,2,FALSE)) -> IAGON
A126: 25c5de5f5b286073c593edfd77b48abc7a48e5a4f3d4cd9d428ff935.425443 | B126: 5d16cc1a177b5d9ba9cfa9793b07e60f1fb70fea1f8aef064415d114.494147 | C126: 8000 | D126: TRUE | E126: =IF(A126="","ADA",VLOOKUP(A126,'All float token'!A$2:B$64,2,FALSE)) -> BTC | F126: =IF(B126="","ADA",VLOOKUP(B126,'All float token'!A$2:B$64,2,FALSE)) -> IAGON
A127: 25c5de5f5b286073c593edfd77b48abc7a48e5a4f3d4cd9d428ff935.55534443 | B127: 5d16cc1a177b5d9ba9cfa9793b07e60f1fb70fea1f8aef064415d114.494147 | C127: 8000 | D127: TRUE | E127: =IF(A127="","ADA",VLOOKUP(A127,'All float token'!A$2:B$64,2,FALSE)) -> USDC | F127: =IF(B127="","ADA",VLOOKUP(B127,'All float token'!A$2:B$64,2,FALSE)) -> IAGON
A128: 25c5de5f5b286073c593edfd77b48abc7a48e5a4f3d4cd9d428ff935.55534454 | B128: 5d16cc1a177b5d9ba9cfa9793b07e60f1fb70fea1f8aef064415d114.494147 | C128: 8000 | D128: TRUE | E128: =IF(A128="","ADA",VLOOKUP(A128,'All float token'!A$2:B$64,2,FALSE)) -> USDT | F128: =IF(B128="","ADA",VLOOKUP(B128,'All float token'!A$2:B$64,2,FALSE)) -> IAGON
A129: 279c909f348e533da5808898f87f9a14bb2c3dfbbacccd631d927a3f.534e454b | B129: 5d16cc1a177b5d9ba9cfa9793b07e60f1fb70fea1f8aef064415d114.494147 | C129: 6000 | D129: TRUE | E129: =IF(A129="","ADA",VLOOKUP(A129,'All float token'!A$2:B$64,2,FALSE)) -> Snek | F129: =IF(B129="","ADA",VLOOKUP(B129,'All float token'!A$2:B$64,2,FALSE)) -> IAGON
A130: 2852268cf6e2db42e20f2fd3125f541e5d6c5a3d70b4dda17c2daa82 | B130: 5d16cc1a177b5d9ba9cfa9793b07e60f1fb70fea1f8aef064415d114.494147 | C130: 6000 | D130: TRUE | E130: =IF(A130="","ADA",VLOOKUP(A130,'All float token'!A$2:B$64,2,FALSE)) -> The O Token | F130: =IF(B130="","ADA",VLOOKUP(B130,'All float token'!A$2:B$64,2,FALSE)) -> IAGON
A131: 29d222ce763455e3d7a09a665ce554f00ac89d2e99a1a83d267170c6.4d494e | B131: 5d16cc1a177b5d9ba9cfa9793b07e60f1fb70fea1f8aef064415d114.494147 | C131: 6000 | D131: TRUE | E131: =IF(A131="","ADA",VLOOKUP(A131,'All float token'!A$2:B$64,2,FALSE)) -> Minswap | F131: =IF(B131="","ADA",VLOOKUP(B131,'All float token'!A$2:B$64,2,FALSE)) -> IAGON
A132: 2d9db8a89f074aa045eab177f23a3395f62ced8b53499a9e4ad46c80.464c4f57 | B132: 5d16cc1a177b5d9ba9cfa9793b07e60f1fb70fea1f8aef064415d114.494147 | C132: 6000 | D132: TRUE | E132: =IF(A132="","ADA",VLOOKUP(A132,'All float token'!A$2:B$64,2,FALSE)) -> FLOW | F132: =IF(B132="","ADA",VLOOKUP(B132,'All float token'!A$2:B$64,2,FALSE)) -> IAGON
...

Sheet NewToken
A1: supply_token | B1: collaterals
B2: [{"token":"09f4212b4f1c4a2d1300866e8decec795abb8eb8bbdc34d2d66384fd.555344545f4144415f4c51","threshold":8000,"enable":true},{"token":"0a0a692605bed9e698a172a35adbdb70a04b40273c9043e1c4e4570a.0014efbfbd105553444d5f4144415f4c51","threshold":8000,"enable":true},{"token":"0d91892d31eef2398d66e771a03feea04ca17cd26655c2cc1550514a.555344415f4144415f4c51","threshold":8000,"enable":true},{"token":"25c5de5f5b286073c593edfd77b48abc7a48e5a4f3d4cd9d428ff935.425443","threshold":8000,"enable":true},{"token":"25c5de5f5b286073c593edfd77b48abc7a48e5a4f3d4cd9d428ff935.55534443","threshold":8000,"enable":true},{"token":"25c5de5f5b286073c593edfd77b48abc7a48e5a4f3d4cd9d428ff935.55534454","threshold":8000,"enable":true},{"token":"4cf6a914372155ec78f6643141e280d38e3bae4ffbf623765efce3de.4254435f4144415f4c51","threshold":8000,"enable":true},{"token":"6df63e2fdde8b2c3b3396265b0cc824aa4fb999396b1c154280f6b0c","threshold":8000,"enable":true},{"token":"6ebaa7305f90791b9fae1c0bbbc9a3a1820088b621e95193df396772.4254435f4144415f4c51","threshold":8000,"enable":true},{"token":"7a4d45e6b4e6835c4cea3968f291fab3704949cfd2f2dc1997c4eeec","threshold":8000,"enable":true},{"token":"7b7976222e874b1ac7c34fc5a56563203f7562fb217068242f7f5059.446a65644d6963726f5553445f4144415f4c51","threshold":8000,"enable":true},{"token":"8db269c3ec630e06ae29f74bc39edd1f87c819f1056206e879a1cd61.446a65644d6963726f555344","threshold":8000,"enable":true},{"token":"94dca24a1f1fcc2ff51cd90f32f4fe9e786d861a2dbf7d27598d26e8.134ab43b73bd6f5ae70534fe51194ad62618d39a539830ecef4f8e19","threshold":8000,"enable":true},{"token":"94dca24a1f1fcc2ff51cd90f32f4fe9e786d861a2dbf7d27598d26e8.2212068512d00ba78800e493bce47121d492043c864d896ea9f5ad5c","threshold":8000,"enable":true},{"token":"94dca24a1f1fcc2ff51cd90f32f4fe9e786d861a2dbf7d27598d26e8.2d94b144d91520d0de771f6c3449d5cff8f0373c472dae2b9851a8c2","threshold":8000,"enable":true},{"token":"94dca24a1f1fcc2ff51cd90f32f4fe9e786d861a2dbf7d27598d26e8.7553c4258a557314d787908085e67fb50f7d6f8f6ff6e0d1c9b9306b","threshold":8000,"enable":true},{"token":"94dca24a1f1fcc2ff51cd90f32f4fe9e786d861a2dbf7d27598d26e8.a90873033a7449a360ab4a9b07b7262cad46a54031d09d784cf01127","threshold":8000,"enable":true},{"token":"94dca24a1f1fcc2ff51cd90f32f4fe9e786d861a2dbf7d27598d26e8.b96f6167426d625b8975c0437966745c9240e6488517b2b2f44bc7c7","threshold":8000,"enable":true},{"token":"9e00df0615de0a7b121a7f961d43e23165b8e81b64786c6eb708d370","threshold":8000,"enable":true},{"token":"aa280c98c5b07fdfc8d7a93fb5ba84510b421388e4a18e16efa8eb5f","threshold":8000,"enable":true},{"token":"aebcb6eaba17dea962008a9d693e39a3160b02b5b89b1c83e537c599","threshold":8000,"enable":true},{"token":"c48cbb3d5e57ed56e276bc45f99ab39abe94e6cd7ac39fb402da47ad.0014df105553444d","threshold":8000,"enable":true},{"token":"dd83cb88459772bd3c4bd2afd55bf005832be922ff13df5422289a94.555344435f4144415f4c51","threshold":8000,"enable":true},{"token":"e29b474dccd09382fb0c93458995fffee6e6bb3285fb4c0bae01e216.0014df105553444d5f4144415f4c51","threshold":8000,"enable":true},{"token":"f5808c2c990d86da54bfc97d89cee6efa20cd8461616359478d96b4c.3cb4b74763277162c3d4548c2af1829b79c41e2dd1ac7560504cbd5e82b1e971","threshold":8000,"enable":true},{"token":"f5808c2c990d86da54bfc97d89cee6efa20cd8461616359478d96b4c.478773ab4e6f800e72e4210a80adc5b086eb6f42bf493591dbdcec4ae9a692f7","threshold":8000,"enable":true},{"token":"f5808c2c990d86da54bfc97d89cee6efa20cd8461616359478d96b4c.55058d3f832e6bb577ca8bb354c0c736dc4ca4e80798a82c17a956ee278872d3","threshold":8000,"enable":true},{"token":"f5808c2c990d86da54bfc97d89cee6efa20cd8461616359478d96b4c.7dd6988c5a86693c76aeec1ea94afa41770be0de21a775ca7a2a1eabdb6a0171","threshold":8000,"enable":true},{"token":"f5808c2c990d86da54bfc97d89cee6efa20cd8461616359478d96b4c.a939812d08cfb6066e17d2914a7272c6b8c0197acdf68157d02c73649cc3efc0","threshold":8000,"enable":true},{"token":"f5808c2c990d86da54bfc97d89cee6efa20cd8461616359478d96b4c.ee5cfbc5b0dc10c873a0bcc69e49b9af21b899f59337a894874c6b596c2da136","threshold":8000,"enable":true},{"token":"f72166e9fac8297aeb553c19ffab14f51ae271c2cb26783ba289a3a5","threshold":8000,"enable":true},{"token":"fe7c786ab321f41c654ef6c1af7b3250a613c24e4213e0425a7ae456.55534441","threshold":8000,"enable":true}]
A3: c48cbb3d5e57ed56e276bc45f99ab39abe94e6cd7ac39fb402da47ad.0014df105553444d | B3: [{"token":"","threshold":8000,"enable":true},{"token":"09f4212b4f1c4a2d1300866e8decec795abb8eb8bbdc34d2d66384fd.555344545f4144415f4c51","threshold":8000,"enable":true},{"token":"0a0a692605bed9e698a172a35adbdb70a04b40273c9043e1c4e4570a.0014efbfbd105553444d5f4144415f4c51","threshold":8000,"enable":true},{"token":"0d91892d31eef2398d66e771a03feea04ca17cd26655c2cc1550514a.555344415f4144415f4c51","threshold":8000,"enable":true},{"token":"25c5de5f5b286073c593edfd77b48abc7a48e5a4f3d4cd9d428ff935.425443","threshold":8000,"enable":true},{"token":"25c5de5f5b286073c593edfd77b48abc7a48e5a4f3d4cd9d428ff935.55534443","threshold":9000,"enable":true},{"token":"25c5de5f5b286073c593edfd77b48abc7a48e5a4f3d4cd9d428ff935.55534454","threshold":9000,"enable":true},{"token":"4cf6a914372155ec78f6643141e280d38e3bae4ffbf623765efce3de.4254435f4144415f4c51","threshold":8000,"enable":true},{"token":"6df63e2fdde8b2c3b3396265b0cc824aa4fb999396b1c154280f6b0c","threshold":9000,"enable":true},{"token":"6ebaa7305f90791b9fae1c0bbbc9a3a1820088b621e95193df396772.4254435f4144415f4c51","threshold":8000,"enable":true},{"token":"7a4d45e6b4e6835c4cea3968f291fab3704949cfd2f2dc1997c4eeec","threshold":9000,"enable":true},{"token":"7b7976222e874b1ac7c34fc5a56563203f7562fb217068242f7f5059.446a65644d6963726f5553445f4144415f4c51","threshold":8000,"enable":true},{"token":"8db269c3ec630e06ae29f74bc39edd1f87c819f1056206e879a1cd61.446a65644d6963726f555344","threshold":9000,"enable":true},{"token":"94dca24a1f1fcc2ff51cd90f32f4fe9e786d861a2dbf7d27598d26e8.134ab43b73bd6f5ae70534fe51194ad62618d39a539830ecef4f8e19","threshold":8000,"enable":true},{"token":"94dca24a1f1fcc2ff51cd90f32f4fe9e786d861a2dbf7d27598d26e8.2d94b144d91520d0de771f6c3449d5cff8f0373c472dae2b9851a8c2","threshold":9000,"enable":true},{"token":"94dca24a1f1fcc2ff51cd90f32f4fe9e786d861a2dbf7d27598d26e8.7553c4258a557314d787908085e67fb50f7d6f8f6ff6e0d1c9b9306b","threshold":9000,"enable":true},{"token":"94dca24a1f1fcc2ff51cd90f32f4fe9e786d861a2dbf7d27598d26e8.a90873033a7449a360ab4a9b07b7262cad46a54031d09d784cf01127","threshold":9000,"enable":true},{"token":"94dca24a1f1fcc2ff51cd90f32f4fe9e786d861a2dbf7d27598d26e8.b96f6167426d625b8975c0437966745c9240e6488517b2b2f44bc7c7","threshold":9000,"enable":true},{"token":"94dca24a1f1fcc2ff51cd90f32f4fe9e786d861a2dbf7d27598d26e8.f04403181fbd051edd971af67b85f6c6fe1d9d98949a80b9f3803a14","threshold":8000,"enable":true},{"token":"a04ce7a52545e5e33c2867e148898d9e667a69602285f6a1298f9d68","threshold":8000,"enable":true},{"token":"aa280c98c5b07fdfc8d7a93fb5ba84510b421388e4a18e16efa8eb5f","threshold":9000,"enable":true},{"token":"aebcb6eaba17dea962008a9d693e39a3160b02b5b89b1c83e537c599","threshold":9000,"enable":true},{"token":"dd83cb88459772bd3c4bd2afd55bf005832be922ff13df5422289a94.555344435f4144415f4c51","threshold":8000,"enable":true},{"token":"e29b474dccd09382fb0c93458995fffee6e6bb3285fb4c0bae01e216.0014df105553444d5f4144415f4c51","threshold":8000,"enable":true},{"token":"f5808c2c990d86da54bfc97d89cee6efa20cd8461616359478d96b4c.3cb4b74763277162c3d4548c2af1829b79c41e2dd1ac7560504cbd5e82b1e971","threshold":8000,"enable":true},{"token":"f5808c2c990d86da54bfc97d89cee6efa20cd8461616359478d96b4c.478773ab4e6f800e72e4210a80adc5b086eb6f42bf493591dbdcec4ae9a692f7","threshold":8000,"enable":true},{"token":"f5808c2c990d86da54bfc97d89cee6efa20cd8461616359478d96b4c.55058d3f832e6bb577ca8bb354c0c736dc4ca4e80798a82c17a956ee278872d3","threshold":8000,"enable":true},{"token":"f5808c2c990d86da54bfc97d89cee6efa20cd8461616359478d96b4c.7dd6988c5a86693c76aeec1ea94afa41770be0de21a775ca7a2a1eabdb6a0171","threshold":8000,"enable":true},{"token":"f5808c2c990d86da54bfc97d89cee6efa20cd8461616359478d96b4c.a939812d08cfb6066e17d2914a7272c6b8c0197acdf68157d02c73649cc3efc0","threshold":8000,"enable":true},{"token":"f5808c2c990d86da54bfc97d89cee6efa20cd8461616359478d96b4c.ee5cfbc5b0dc10c873a0bcc69e49b9af21b899f59337a894874c6b596c2da136","threshold":8000,"enable":true},{"token":"f72166e9fac8297aeb553c19ffab14f51ae271c2cb26783ba289a3a5","threshold":8000,"enable":true},{"token":"fe7c786ab321f41c654ef6c1af7b3250a613c24e4213e0425a7ae456.55534441","threshold":9000,"enable":true}]
A4: fe7c786ab321f41c654ef6c1af7b3250a613c24e4213e0425a7ae456.55534441 | B4: [{"token":"","threshold":8000,"enable":true},{"token":"09f4212b4f1c4a2d1300866e8decec795abb8eb8bbdc34d2d66384fd.555344545f4144415f4c51","threshold":8000,"enable":true},{"token":"0a0a692605bed9e698a172a35adbdb70a04b40273c9043e1c4e4570a.0014efbfbd105553444d5f4144415f4c51","threshold":8000,"enable":true},{"token":"0d91892d31eef2398d66e771a03feea04ca17cd26655c2cc1550514a.555344415f4144415f4c51","threshold":8000,"enable":true},{"token":"25c5de5f5b286073c593edfd77b48abc7a48e5a4f3d4cd9d428ff935.425443","threshold":8000,"enable":true},{"token":"25c5de5f5b286073c593edfd77b48abc7a48e5a4f3d4cd9d428ff935.55534443","threshold":9000,"enable":true},{"token":"25c5de5f5b286073c593edfd77b48abc7a48e5a4f3d4cd9d428ff935.55534454","threshold":9000,"enable":true},{"token":"4cf6a914372155ec78f6643141e280d38e3bae4ffbf623765efce3de.4254435f4144415f4c51","threshold":8000,"enable":true},{"token":"6df63e2fdde8b2c3b3396265b0cc824aa4fb999396b1c154280f6b0c","threshold":9000,"enable":true},{"token":"6ebaa7305f90791b9fae1c0bbbc9a3a1820088b621e95193df396772.4254435f4144415f4c51","threshold":8000,"enable":true},{"token":"7a4d45e6b4e6835c4cea3968f291fab3704949cfd2f2dc1997c4eeec","threshold":9000,"enable":true},{"token":"7b7976222e874b1ac7c34fc5a56563203f7562fb217068242f7f5059.446a65644d6963726f5553445f4144415f4c51","threshold":8000,"enable":true},{"token":"8db269c3ec630e06ae29f74bc39edd1f87c819f1056206e879a1cd61.446a65644d6963726f555344","threshold":9000,"enable":true},{"token":"94dca24a1f1fcc2ff51cd90f32f4fe9e786d861a2dbf7d27598d26e8.134ab43b73bd6f5ae70534fe51194ad62618d39a539830ecef4f8e19","threshold":8000,"enable":true},{"token":"94dca24a1f1fcc2ff51cd90f32f4fe9e786d861a2dbf7d27598d26e8.2212068512d00ba78800e493bce47121d492043c864d896ea9f5ad5c","threshold":9000,"enable":true},{"token":"94dca24a1f1fcc2ff51cd90f32f4fe9e786d861a2dbf7d27598d26e8.2d94b144d91520d0de771f6c3449d5cff8f0373c472dae2b9851a8c2","threshold":9000,"enable":true},{"token":"94dca24a1f1fcc2ff51cd90f32f4fe9e786d861a2dbf7d27598d26e8.a90873033a7449a360ab4a9b07b7262cad46a54031d09d784cf01127","threshold":9000,"enable":true},{"token":"94dca24a1f1fcc2ff51cd90f32f4fe9e786d861a2dbf7d27598d26e8.b96f6167426d625b8975c0437966745c9240e6488517b2b2f44bc7c7","threshold":9000,"enable":true},{"token":"94dca24a1f1fcc2ff51cd90f32f4fe9e786d861a2dbf7d27598d26e8.f04403181fbd051edd971af67b85f6c6fe1d9d98949a80b9f3803a14","threshold":8000,"enable":true},{"token":"9e00df0615de0a7b121a7f961d43e23165b8e81b64786c6eb708d370","threshold":9000,"enable":true},{"token":"a04ce7a52545e5e33c2867e148898d9e667a69602285f6a1298f9d68","threshold":8000,"enable":true},{"token":"aebcb6eaba17dea962008a9d693e39a3160b02b5b89b1c83e537c599","threshold":9000,"enable":true},{"token":"c48cbb3d5e57ed56e276bc45f99ab39abe94e6cd7ac39fb402da47ad.0014df105553444d","threshold":9000,"enable":true},{"token":"dd83cb88459772bd3c4bd2afd55bf005832be922ff13df5422289a94.555344435f4144415f4c51","threshold":8000,"enable":true},{"token":"e29b474dccd09382fb0c93458995fffee6e6bb3285fb4c0bae01e216.0014df105553444d5f4144415f4c51","threshold":8000,"enable":true},{"token":"f5808c2c990d86da54bfc97d89cee6efa20cd8461616359478d96b4c.3cb4b74763277162c3d4548c2af1829b79c41e2dd1ac7560504cbd5e82b1e971","threshold":8000,"enable":true},{"token":"f5808c2c990d86da54bfc97d89cee6efa20cd8461616359478d96b4c.478773ab4e6f800e72e4210a80adc5b086eb6f42bf493591dbdcec4ae9a692f7","threshold":8000,"enable":true},{"token":"f5808c2c990d86da54bfc97d89cee6efa20cd8461616359478d96b4c.55058d3f832e6bb577ca8bb354c0c736dc4ca4e80798a82c17a956ee278872d3","threshold":8000,"enable":true},{"token":"f5808c2c990d86da54bfc97d89cee6efa20cd8461616359478d96b4c.7dd6988c5a86693c76aeec1ea94afa41770be0de21a775ca7a2a1eabdb6a0171","threshold":8000,"enable":true},{"token":"f5808c2c990d86da54bfc97d89cee6efa20cd8461616359478d96b4c.a939812d08cfb6066e17d2914a7272c6b8c0197acdf68157d02c73649cc3efc0","threshold":8000,"enable":true},{"token":"f5808c2c990d86da54bfc97d89cee6efa20cd8461616359478d96b4c.ee5cfbc5b0dc10c873a0bcc69e49b9af21b899f59337a894874c6b596c2da136","threshold":8000,"enable":true},{"token":"f72166e9fac8297aeb553c19ffab14f51ae271c2cb26783ba289a3a5","threshold":8000,"enable":true}]
